{"trial_id": "0000", "hyperparameters": {"space": [{"class_name": "Int", "config": {"name": "units", "default": null, "conditions": [], "min_value": 32, "max_value": 1024, "step": 32, "sampling": "linear"}}, {"class_name": "Float", "config": {"name": "learning_rate", "default": 0.0001, "conditions": [], "min_value": 0.0001, "max_value": 0.01, "step": null, "sampling": "log"}}], "values": {"units": 928, "learning_rate": 0.0030841253431867954, "tuner/epochs": 2, "tuner/initial_epoch": 0, "tuner/bracket": 2, "tuner/round": 0}}, "metrics": {"metrics": {}}, "score": null, "best_step": 0, "status": "FAILED", "message": "Traceback (most recent call last):\n  File \"/Users/arjunmoorthy/miniconda3/envs/torch/lib/python3.11/site-packages/keras_tuner/src/engine/base_tuner.py\", line 274, in _try_run_and_update_trial\n    self._run_and_update_trial(trial, *fit_args, **fit_kwargs)\n  File \"/Users/arjunmoorthy/miniconda3/envs/torch/lib/python3.11/site-packages/keras_tuner/src/engine/base_tuner.py\", line 239, in _run_and_update_trial\n    results = self.run_trial(trial, *fit_args, **fit_kwargs)\n              ^^^^^^^^^^^^^^^^^^^^^^^^^^^^^^^^^^^^^^^^^^^^^^\n  File \"/Users/arjunmoorthy/miniconda3/envs/torch/lib/python3.11/site-packages/keras_tuner/src/tuners/hyperband.py\", line 427, in run_trial\n    return super().run_trial(trial, *fit_args, **fit_kwargs)\n           ^^^^^^^^^^^^^^^^^^^^^^^^^^^^^^^^^^^^^^^^^^^^^^^^^\n  File \"/Users/arjunmoorthy/miniconda3/envs/torch/lib/python3.11/site-packages/keras_tuner/src/engine/tuner.py\", line 314, in run_trial\n    obj_value = self._build_and_fit_model(trial, *args, **copied_kwargs)\n                ^^^^^^^^^^^^^^^^^^^^^^^^^^^^^^^^^^^^^^^^^^^^^^^^^^^^^^^^\n  File \"/Users/arjunmoorthy/miniconda3/envs/torch/lib/python3.11/site-packages/keras_tuner/src/engine/tuner.py\", line 233, in _build_and_fit_model\n    results = self.hypermodel.fit(hp, model, *args, **kwargs)\n              ^^^^^^^^^^^^^^^^^^^^^^^^^^^^^^^^^^^^^^^^^^^^^^^\n  File \"/Users/arjunmoorthy/miniconda3/envs/torch/lib/python3.11/site-packages/keras_tuner/src/engine/hypermodel.py\", line 149, in fit\n    return model.fit(*args, **kwargs)\n           ^^^^^^^^^^^^^^^^^^^^^^^^^^\n  File \"/Users/arjunmoorthy/miniconda3/envs/torch/lib/python3.11/site-packages/keras/src/utils/traceback_utils.py\", line 122, in error_handler\n    raise e.with_traceback(filtered_tb) from None\n  File \"/Users/arjunmoorthy/miniconda3/envs/torch/lib/python3.11/site-packages/keras/src/models/functional.py\", line 280, in _adjust_input_rank\n    raise ValueError(\nValueError: Exception encountered when calling Functional.call().\n\n\u001b[1mInvalid input shape for input Tensor(\"data:0\", shape=(None, 256, 256), dtype=float32). Expected shape (None, 256, 256, 3), but input has incompatible shape (None, 256, 256)\u001b[0m\n\nArguments received by Functional.call():\n  \u2022 inputs=tf.Tensor(shape=(None, 256, 256), dtype=float32)\n  \u2022 training=True\n  \u2022 mask=None\n"}